<?xml version="1.0" encoding="UTF-8"?>
<!-- Generated by org.testng.reporters.JUnitReportReporter -->
<testsuite skipped="0" hostname="DESKTOP-69OQC4Q" name="com.aspire.framework.testNG.AssertOwn" tests="7" failures="1" timestamp="2022-02-24T07:32:22 IST" time="0.057" errors="0">
  <testcase name="TC3" time="0.006" classname="com.aspire.framework.testNG.AssertOwn"/>
  <system-out/>
  <testcase name="TC7" time="0.003" classname="com.aspire.framework.testNG.AssertOwn">
    <failure type="java.lang.AssertionError" message="null">
      <![CDATA[java.lang.AssertionError: null
at org.testng.Assert.fail(Assert.java:99)
at org.testng.Assert.fail(Assert.java:106)
at com.aspire.framework.testNG.AssertOwn.TC7(AssertOwn.java:68)
at sun.reflect.NativeMethodAccessorImpl.invoke0(Native Method)
at sun.reflect.NativeMethodAccessorImpl.invoke(Unknown Source)
at sun.reflect.DelegatingMethodAccessorImpl.invoke(Unknown Source)
at java.lang.reflect.Method.invoke(Unknown Source)
at org.testng.internal.MethodInvocationHelper.invokeMethod(MethodInvocationHelper.java:133)
at org.testng.internal.TestInvoker.invokeMethod(TestInvoker.java:598)
at org.testng.internal.TestInvoker.invokeTestMethod(TestInvoker.java:173)
at org.testng.internal.MethodRunner.runInSequence(MethodRunner.java:46)
at org.testng.internal.TestInvoker$MethodInvocationAgent.invoke(TestInvoker.java:824)
at org.testng.internal.TestInvoker.invokeTestMethods(TestInvoker.java:146)
at org.testng.internal.TestMethodWorker.invokeTestMethods(TestMethodWorker.java:146)
at org.testng.internal.TestMethodWorker.run(TestMethodWorker.java:128)
at java.util.ArrayList.forEach(Unknown Source)
at org.testng.TestRunner.privateRun(TestRunner.java:794)
at org.testng.TestRunner.run(TestRunner.java:596)
at org.testng.SuiteRunner.runTest(SuiteRunner.java:377)
at org.testng.SuiteRunner.runSequentially(SuiteRunner.java:371)
at org.testng.SuiteRunner.privateRun(SuiteRunner.java:332)
at org.testng.SuiteRunner.run(SuiteRunner.java:276)
at org.testng.SuiteRunnerWorker.runSuite(SuiteRunnerWorker.java:53)
at org.testng.SuiteRunnerWorker.run(SuiteRunnerWorker.java:96)
at org.testng.TestNG.runSuitesSequentially(TestNG.java:1212)
at org.testng.TestNG.runSuitesLocally(TestNG.java:1134)
at org.testng.TestNG.runSuites(TestNG.java:1063)
at org.testng.TestNG.run(TestNG.java:1031)
at org.testng.remote.AbstractRemoteTestNG.run(AbstractRemoteTestNG.java:115)
at org.testng.remote.RemoteTestNG.initAndRun(RemoteTestNG.java:251)
at org.testng.remote.RemoteTestNG.main(RemoteTestNG.java:77)
]]>
    </failure>
  </testcase> <!-- TC7 -->
  <system-out/>
  <testcase name="TC5" time="0.004" classname="com.aspire.framework.testNG.AssertOwn"/>
  <system-out/>
  <testcase name="TC6" time="0.002" classname="com.aspire.framework.testNG.AssertOwn"/>
  <system-out/>
  <testcase name="TC" time="0.032" classname="com.aspire.framework.testNG.AssertOwn"/>
  <system-out/>
  <testcase name="TC2" time="0.007" classname="com.aspire.framework.testNG.AssertOwn"/>
  <system-out/>
  <testcase name="TC4" time="0.003" classname="com.aspire.framework.testNG.AssertOwn"/>
  <system-out/>
</testsuite> <!-- com.aspire.framework.testNG.AssertOwn -->
